<?xml version="1.0" ?>
<!-- =================================================================================== -->
<!-- |    This document was autogenerated by xacro from c_iartemis_urdf_model_fixed.urdf.xacro | -->
<!-- |    EDITING THIS FILE BY HAND IS NOT RECOMMENDED                                 | -->
<!-- =================================================================================== -->
<robot name="iartemis" xmlns:body="http://playerstage.sourceforge.net/gazebo/xmlschema/#body" xmlns:controller="http://playerstage.sourceforge.net/gazebo/xmlschema/#controller" xmlns:gazebo="http://playerstage.sourceforge.net/gazebo/xmlschema/#gazebo" xmlns:geom="http://playerstage.sourceforge.net/gazebo/xmlschema/#geom" xmlns:interface="http://playerstage.sourceforge.net/gazebo/xmlschema/#interface" xmlns:joint="http://playerstage.sourceforge.net/gazebo/xmlschema/#joint" xmlns:model="http://playerstage.sourceforge.net/gazebo/xmlschema/#model" xmlns:physics="http://playerstage.sourceforge.net/gazebo/xmlschema/#physics" xmlns:xacro="http://ros.org/wiki/xacro">
  <material name="blue">
    <color rgba="0 0 .8 1"/>
  </material>
  <material name="black">
    <color rgba="0 0 0 1"/>
  </material>
  <material name="white">
    <color rgba="1 1 1 1"/>
  </material>
  <material name="grey">
    <color rgba=".5 .5 .5 1"/>
  </material>
  <!-- base_link -->
  <link name="base_link">
    <visual>
      <geometry>
        <box size="0.154 0.14 0.128"/>
      </geometry>
      <material name="grey"/>
    </visual>
    <collision>
      <geometry>
        <box size="0.154 0.14 0.128"/>
      </geometry>
    </collision>
    <!-- <xacro:default_inertial mass="10"/>-->
  </link>
  <gazebo reference="base_link">
    <material>Gazebo/Grey</material>
  </gazebo>
  <!-- middle axis -->
  <!-- middle_triangle_base -->
  <link name="middle_triangle_base">
    <visual>
      <geometry>
        <box size="0.140 .010 .010"/>
      </geometry>
      <origin rpy="0 0 1.57075" xyz="0 0 0"/>
      <material name="grey"/>
    </visual>
    <collision>
      <geometry>
        <box size="0.140 .010 .010"/>
      </geometry>
      <origin rpy="0 0 1.57075" xyz="0 0 0"/>
    </collision>
    <inertial>
      <mass value="1"/>
      <inertia ixx="1.0" ixy="0.0" ixz="0.0" iyy="1.0" iyz="0.0" izz="1.0"/>
    </inertial>
  </link>
  <gazebo reference="middle_triangle_base">
    </gazebo>
  <joint name="base_link_to_middle_triangle_base" type="fixed">
    <parent link="base_link"/>
    <child link="middle_triangle_base"/>
    <origin rpy="0 0 0" xyz="0 0 -0.064"/>
    <dynamics damping="0.0" friction="0.0"/>
  </joint>
  <!-- middle_left_triangle_side -->
  <link name="middle_left_triangle_side">
    <visual>
      <geometry>
        <box size="0.189409609 .010 .010"/>
      </geometry>
      <origin rpy="0 0 2.763000731" xyz="-0.088 -0.035 0"/>
      <material name="grey"/>
    </visual>
    <collision>
      <geometry>
        <box size="0.189409609 .010 .010"/>
      </geometry>
      <origin rpy="0 0 2.763000731" xyz="-0.088 -0.035 0"/>
    </collision>
    <inertial>
      <mass value="1"/>
      <inertia ixx="1.0" ixy="0.0" ixz="0.0" iyy="1.0" iyz="0.0" izz="1.0"/>
    </inertial>
  </link>
  <gazebo reference="middle_left_triangle_side">
    </gazebo>
  <joint name="middle_triangle_base_to_middle_left_triangle_side" type="fixed">
    <parent link="middle_triangle_base"/>
    <child link="middle_left_triangle_side"/>
    <origin rpy="0 1.57075 0" xyz="0 0 0"/>
    <dynamics damping="0.0" friction="0.0"/>
  </joint>
  <!-- middle_right_triangle_side -->
  <link name="middle_right_triangle_side">
    <visual>
      <geometry>
        <box size="0.189409609 .010 .010"/>
      </geometry>
      <origin rpy="0 0 0.378499269" xyz="-0.088 0.035 0"/>
      <material name="grey"/>
    </visual>
    <collision>
      <geometry>
        <box size="0.189409609 .010 .010"/>
      </geometry>
      <origin rpy="0 0 0.378499269" xyz="-0.088 0.035 0"/>
    </collision>
    <inertial>
      <mass value="1"/>
      <inertia ixx="1.0" ixy="0.0" ixz="0.0" iyy="1.0" iyz="0.0" izz="1.0"/>
    </inertial>
  </link>
  <gazebo reference="middle_right_triangle_side">
    </gazebo>
  <joint name="middle_triangle_base_to_middle_right_triangle_side" type="fixed">
    <parent link="middle_triangle_base"/>
    <child link="middle_right_triangle_side"/>
    <origin rpy="0 1.57075 0" xyz="0 0 0"/>
    <dynamics damping="0.0" friction="0.0"/>
  </joint>
  <!-- middle_right_direction_axis -->
  <link name="middle_right_direction_axis">
    <visual>
      <geometry>
        <cylinder length="0.330134821" radius="0.005"/>
      </geometry>
      <origin rpy="1.74735236 0 0" xyz="0 -0.1625 -0.029"/>
      <material name="grey"/>
    </visual>
    <collision>
      <geometry>
        <cylinder length="0.399235519" radius="0.005"/>
      </geometry>
      <origin rpy="1.74735236 0 0" xyz="0 -0.1625 -0.029"/>
    </collision>
    <inertial>
      <mass value="1"/>
      <inertia ixx="1.0" ixy="0.0" ixz="0.0" iyy="1.0" iyz="0.0" izz="1.0"/>
    </inertial>
  </link>
  <gazebo reference="middle_right_direction_axis">
    </gazebo>
  <joint name="middle_triangle_base_to_middle_right_direction_axis" type="fixed">
    <parent link="middle_triangle_base"/>
    <child link="middle_right_direction_axis"/>
    <axis xyz="1 0 0"/>
    <origin rpy="0 0 0" xyz="0 -0.07 0"/>
    <limit effort="0.5293" lower="-1.5" upper="1.5" velocity="6.159937255"/>
    <dynamics damping="0.0" friction="0.0"/>
    <!-- <mimic joint="middle_triangle_base_to_middle_right_balance_support" multiplier="1" offset="0" /> -->
  </joint>
  <!-- middle_left_direction_axis -->
  <link name="middle_left_direction_axis">
    <visual>
      <geometry>
        <cylinder length="0.330134821" radius="0.005"/>
      </geometry>
      <origin rpy="1.39414764 0 0" xyz="0 0.1625 -0.029"/>
      <material name="grey"/>
    </visual>
    <collision>
      <geometry>
        <cylinder length="0.399235519" radius="0.005"/>
      </geometry>
      <origin rpy="1.39414764 0 0" xyz="0 0.1625 -0.029"/>
    </collision>
    <inertial>
      <mass value="1"/>
      <inertia ixx="1.0" ixy="0.0" ixz="0.0" iyy="1.0" iyz="0.0" izz="1.0"/>
    </inertial>
  </link>
  <gazebo reference="middle_left_direction_axis">
    </gazebo>
  <joint name="middle_triangle_base_to_middle_left_direction_axis" type="fixed">
    <parent link="middle_triangle_base"/>
    <child link="middle_left_direction_axis"/>
    <axis xyz="1 0 0"/>
    <origin rpy="0 0 0" xyz="0 0.07 0"/>
    <limit effort="0.5293" lower="-1.5" upper="1.5" velocity="6.159937255"/>
    <dynamics damping="0.0" friction="0.0"/>
    <!-- <mimic joint="middle_triangle_base_to_middle_right_balance_support" multiplier="1" offset="0" /> -->
  </joint>
  <!-- middle_right_steering_support -->
  <link name="middle_right_steering_support">
    <visual>
      <geometry>
        <cylinder length="0.138610966" radius="0.005"/>
      </geometry>
      <origin rpy="3.047620612 0 0" xyz="0 0.0065 0.069"/>
      <material name="grey"/>
    </visual>
    <collision>
      <geometry>
        <cylinder length="0.138610966" radius="0.005"/>
      </geometry>
      <origin rpy="3.047620612 0 0" xyz="0 0.0065 0.069"/>
    </collision>
    <inertial>
      <mass value="1"/>
      <inertia ixx="1.0" ixy="0.0" ixz="0.0" iyy="1.0" iyz="0.0" izz="1.0"/>
    </inertial>
  </link>
  <gazebo reference="middle_right_steering_support">
    </gazebo>
  <joint name="middle_right_direction_axis_to_middle_right_steering_support" type="fixed">
    <parent link="middle_right_direction_axis"/>
    <child link="middle_right_steering_support"/>
    <axis xyz="1 0 0"/>
    <origin rpy="0 0 0" xyz="0 -0.325 -0.058"/>
    <limit effort="0.5293" lower="-1.5" upper="1.5" velocity="6.159937255"/>
    <dynamics damping="0.0" friction="0.0"/>
    <!-- <mimic joint="middle_triangle_base_to_middle_right_balance_support" multiplier="-1" offset="0" /> -->
  </joint>
  <!-- middle_left_steering_support -->
  <link name="middle_left_steering_support">
    <visual>
      <geometry>
        <cylinder length="0.138610966" radius="0.005"/>
      </geometry>
      <origin rpy="0.093879388 0 0" xyz="0 -0.0065 0.069"/>
      <material name="grey"/>
    </visual>
    <collision>
      <geometry>
        <cylinder length="0.138610966" radius="0.005"/>
      </geometry>
      <origin rpy="0.093879388 0 0" xyz="0 -0.0065 0.069"/>
    </collision>
    <inertial>
      <mass value="1"/>
      <inertia ixx="1.0" ixy="0.0" ixz="0.0" iyy="1.0" iyz="0.0" izz="1.0"/>
    </inertial>
  </link>
  <gazebo reference="middle_left_steering_support">
    </gazebo>
  <joint name="middle_left_direction_axis_to_middle_left_steering_support" type="fixed">
    <parent link="middle_left_direction_axis"/>
    <child link="middle_left_steering_support"/>
    <axis xyz="1 0 0"/>
    <origin rpy="0 0 0" xyz="0 0.325 -0.058"/>
    <limit effort="0.5293" lower="-1.5" upper="1.5" velocity="6.159937255"/>
    <dynamics damping="0.0" friction="0.0"/>
    <!-- <mimic joint="middle_triangle_base_to_middle_right_balance_support" multiplier="-1" offset="0" /> -->
  </joint>
  <!-- middle_right_balance_support -->
  <link name="middle_right_balance_support">
    <visual>
      <geometry>
        <cylinder length="0.39387815374" radius="0.005"/>
      </geometry>
      <origin rpy="1.81696019 0 0" xyz="0 0.191 0.048"/>
      <material name="grey"/>
    </visual>
    <collision>
      <geometry>
        <cylinder length="0.39387815374" radius="0.005"/>
      </geometry>
      <origin rpy="1.81696019 0 0" xyz="0 0.191 0.048"/>
    </collision>
    <inertial>
      <mass value="1"/>
      <inertia ixx="1.0" ixy="0.0" ixz="0.0" iyy="1.0" iyz="0.0" izz="1.0"/>
    </inertial>
  </link>
  <gazebo reference="middle_right_balance_support">
    </gazebo>
  <joint name="middle_right_steering_support_to_middle_right_balance_support" type="fixed">
    <parent link="middle_right_steering_support"/>
    <child link="middle_right_balance_support"/>
    <axis xyz="1 0 0"/>
    <origin rpy="0 0 0" xyz="0 0.013 0.138"/>
    <limit effort="0.5293" lower="-1.5" upper="1.5" velocity="6.159937255"/>
    <dynamics damping="0.0" friction="0.0"/>
  </joint>
  <!-- middle_left_balance_support -->
  <link name="middle_left_balance_support">
    <visual>
      <geometry>
        <cylinder length="0.39387815374" radius="0.005"/>
      </geometry>
      <origin rpy="1.32453981 0 0" xyz="0 -0.191 0.048"/>
      <material name="grey"/>
    </visual>
    <collision>
      <geometry>
        <cylinder length="0.39387815374" radius="0.005"/>
      </geometry>
      <origin rpy="1.32453981 0 0" xyz="0 -0.191 0.048"/>
    </collision>
    <inertial>
      <mass value="1"/>
      <inertia ixx="1.0" ixy="0.0" ixz="0.0" iyy="1.0" iyz="0.0" izz="1.0"/>
    </inertial>
  </link>
  <gazebo reference="middle_left_balance_support">
    </gazebo>
  <joint name="middle_left_steering_support_to_middle_left_balance_support" type="fixed">
    <parent link="middle_left_steering_support"/>
    <child link="middle_left_balance_support"/>
    <axis xyz="1 0 0"/>
    <origin rpy="0 0 0" xyz="0 -0.013 0.138"/>
    <limit effort="0.5293" lower="-1.5" upper="1.5" velocity="6.159937255"/>
    <dynamics damping="0.0" friction="0.0"/>
    <!-- <mimic joint="middle_triangle_base_to_middle_right_balance_support" multiplier="1" offset="0" /> -->
  </joint>
  <link name="middle_left_wheel">
    <visual>
      <origin rpy="1.57075 0 0" xyz="0 0 0"/>
      <geometry>
        <cylinder length="0.146" radius="0.18"/>
      </geometry>
      <material name="black"/>
    </visual>
    <collision>
      <origin rpy="1.57075 0 0" xyz="0 0 0"/>
      <geometry>
        <cylinder length="0.146" radius="0.18"/>
      </geometry>
    </collision>
    <inertial>
      <mass value="5"/>
      <inertia ixx="1.0" ixy="0.0" ixz="0.0" iyy="1.0" iyz="0.0" izz="1.0"/>
    </inertial>
  </link>
  <!-- This block provides the simulator (Gazebo) with information on a few additional
    physical properties. See http://gazebosim.org/tutorials/?tut=ros_urdf for more-->
  <gazebo reference="middle_left_wheel">
    <mu1 value="1.0"/>
    <mu2 value="1.0"/>
    <kp value="10000000.0"/>
    <kd value="1.0"/>
    <material>Gazebo/Grey</material>
  </gazebo>
  <joint name="middle_left_wheel_joint" type="continuous">
    <parent link="middle_left_steering_support"/>
    <child link="middle_left_wheel"/>
    <axis xyz="0 1 0"/>
    <origin rpy="0 0 0" xyz="0 0.073 0"/>
    <dynamics damping="0.0" friction="0.0"/>
  </joint>
  <!-- This block connects the wheel joint to an actuator (motor), which informs both
    simulation and visualization of the robot -->
  <transmission name="middle_left_wheel_trans">
    <type>transmission_interface/SimpleTransmission</type>
    <joint name="middle_left_wheel_joint">
      <hardwareInterface>EffortJointInterface</hardwareInterface>
    </joint>
    <actuator name="middle_left_wheel_motor">
      <mechanicalReduction>1</mechanicalReduction>
    </actuator>
  </transmission>
  <!-- This block connects the head_swivel joint to an actuator (motor), which informs both
  simulation and visualization of the robot -->
  <!-- <transmission name="${prefix}_${suffix}_wheel_trans">
    <type>transmission_interface/SimpleTransmission</type>
    <joint name="${prefix}_${suffix}_wheel_joint"/>
    <actuator name="${prefix}_${suffix}_wheel_motor">
      <hardwareInterface>PositionJointInterface</hardwareInterface>
      <mechanicalReduction>1</mechanicalReduction>
    </actuator>
  </transmission>-->
  <link name="middle_left_wheel_ext">
    <visual>
      <geometry>
        <cylinder length="0.06" radius="0.03"/>
      </geometry>
      <material name="grey"/>
      <origin rpy="0 0 0" xyz="0 0 0"/>
    </visual>
    <collision>
      <geometry>
        <cylinder length="0.06" radius="0.03"/>
      </geometry>
      <origin rpy="0 0 0" xyz="0 0 0"/>
    </collision>
    <inertial>
      <mass value="0"/>
      <inertia ixx="1.0" ixy="0.0" ixz="0.0" iyy="1.0" iyz="0.0" izz="1.0"/>
    </inertial>
  </link>
  <gazebo reference="middle_left_wheel_ext">
    </gazebo>
  <joint name="middle_left_wheel_to_middle_left_wheel_ext" type="fixed">
    <parent link="middle_left_wheel"/>
    <child link="middle_left_wheel_ext"/>
    <axis xyz="0 1 0"/>
    <origin rpy="1.57075 0 0" xyz="0 0.103 0"/>
    <dynamics damping="0.0" friction="0.0"/>
  </joint>
  <link name="middle_right_wheel">
    <visual>
      <origin rpy="1.57075 0 0" xyz="0 0 0"/>
      <geometry>
        <cylinder length="0.146" radius="0.18"/>
      </geometry>
      <material name="black"/>
    </visual>
    <collision>
      <origin rpy="1.57075 0 0" xyz="0 0 0"/>
      <geometry>
        <cylinder length="0.146" radius="0.18"/>
      </geometry>
    </collision>
    <inertial>
      <mass value="5"/>
      <inertia ixx="1.0" ixy="0.0" ixz="0.0" iyy="1.0" iyz="0.0" izz="1.0"/>
    </inertial>
  </link>
  <!-- This block provides the simulator (Gazebo) with information on a few additional
    physical properties. See http://gazebosim.org/tutorials/?tut=ros_urdf for more-->
  <gazebo reference="middle_right_wheel">
    <mu1 value="1.0"/>
    <mu2 value="1.0"/>
    <kp value="10000000.0"/>
    <kd value="1.0"/>
    <material>Gazebo/Grey</material>
  </gazebo>
  <joint name="middle_right_wheel_joint" type="continuous">
    <parent link="middle_right_steering_support"/>
    <child link="middle_right_wheel"/>
    <axis xyz="0 1 0"/>
    <origin rpy="0 0 0" xyz="0 -0.073 0"/>
    <dynamics damping="0.0" friction="0.0"/>
  </joint>
  <!-- This block connects the wheel joint to an actuator (motor), which informs both
    simulation and visualization of the robot -->
  <transmission name="middle_right_wheel_trans">
    <type>transmission_interface/SimpleTransmission</type>
    <joint name="middle_right_wheel_joint">
      <hardwareInterface>EffortJointInterface</hardwareInterface>
    </joint>
    <actuator name="middle_right_wheel_motor">
      <mechanicalReduction>1</mechanicalReduction>
    </actuator>
  </transmission>
  <!-- This block connects the head_swivel joint to an actuator (motor), which informs both
  simulation and visualization of the robot -->
  <!-- <transmission name="${prefix}_${suffix}_wheel_trans">
    <type>transmission_interface/SimpleTransmission</type>
    <joint name="${prefix}_${suffix}_wheel_joint"/>
    <actuator name="${prefix}_${suffix}_wheel_motor">
      <hardwareInterface>PositionJointInterface</hardwareInterface>
      <mechanicalReduction>1</mechanicalReduction>
    </actuator>
  </transmission>-->
  <link name="middle_right_wheel_ext">
    <visual>
      <geometry>
        <cylinder length="0.06" radius="0.03"/>
      </geometry>
      <material name="grey"/>
      <origin rpy="0 0 0" xyz="0 0 0"/>
    </visual>
    <collision>
      <geometry>
        <cylinder length="0.06" radius="0.03"/>
      </geometry>
      <origin rpy="0 0 0" xyz="0 0 0"/>
    </collision>
    <inertial>
      <mass value="0"/>
      <inertia ixx="1.0" ixy="0.0" ixz="0.0" iyy="1.0" iyz="0.0" izz="1.0"/>
    </inertial>
  </link>
  <gazebo reference="middle_right_wheel_ext">
    </gazebo>
  <joint name="middle_right_wheel_to_middle_right_wheel_ext" type="fixed">
    <parent link="middle_right_wheel"/>
    <child link="middle_right_wheel_ext"/>
    <axis xyz="0 1 0"/>
    <origin rpy="1.57075 0 0" xyz="0 -0.103 0"/>
    <dynamics damping="0.0" friction="0.0"/>
  </joint>
  <!-- turret_arm -->
  <link name="turret_arm">
    <visual>
      <geometry>
        <cylinder length="1.320446609" radius="0.01"/>
      </geometry>
      <origin rpy="0 0 0" xyz="0 0 0.9942233045"/>
      <material name="grey"/>
    </visual>
    <collision>
      <geometry>
        <cylinder length="1.320446609" radius="0.01"/>
      </geometry>
      <origin rpy="0 0 0" xyz="0 0 0.9942233045"/>
    </collision>
    <inertial>
      <mass value="1"/>
      <inertia ixx="1.0" ixy="0.0" ixz="0.0" iyy="1.0" iyz="0.0" izz="1.0"/>
    </inertial>
  </link>
  <gazebo reference="turret_arm">
    </gazebo>
  <joint name="base_to_turret_arm" type="fixed">
    <parent link="base_link"/>
    <child link="turret_arm"/>
    <axis xyz="0 1 0"/>
    <origin xyz="0.176001948 -0.019359919 -0.302"/>
    <dynamics damping="0.0" friction="0.0"/>
  </joint>
  <!-- gps_arm -->
  <link name="gps_arm">
    <visual>
      <geometry>
        <cylinder length="0.703868718" radius="0.01"/>
      </geometry>
      <origin rpy="0 0 0" xyz="0 0 0.836934359"/>
      <material name="grey"/>
    </visual>
    <collision>
      <geometry>
        <cylinder length="0.703868718" radius="0.01"/>
      </geometry>
      <origin rpy="0 0 0" xyz="0 0 0.836934359"/>
    </collision>
    <inertial>
      <mass value="1"/>
      <inertia ixx="1.0" ixy="0.0" ixz="0.0" iyy="1.0" iyz="0.0" izz="1.0"/>
    </inertial>
  </link>
  <gazebo reference="gps_arm">
    </gazebo>
  <joint name="base_to_gps_arm" type="fixed">
    <parent link="base_link"/>
    <child link="gps_arm"/>
    <axis xyz="0 1 0"/>
    <origin xyz="-0.027790953 -0.007436771 -0.302"/>
    <dynamics damping="0.0" friction="0.0"/>
  </joint>
  <!-- cam_odom_arm -->
  <link name="cam_odom_arm">
    <visual>
      <geometry>
        <cylinder length="0.667868718" radius="0.01"/>
      </geometry>
      <origin rpy="0 0 0" xyz="0 0 0.635934359"/>
      <material name="grey"/>
    </visual>
    <collision>
      <geometry>
        <cylinder length="0.667868718" radius="0.01"/>
      </geometry>
      <origin rpy="0 0 0" xyz="0 0 0.786934359"/>
    </collision>
    <inertial>
      <mass value="1"/>
      <inertia ixx="1.0" ixy="0.0" ixz="0.0" iyy="1.0" iyz="0.0" izz="1.0"/>
    </inertial>
  </link>
  <gazebo reference="cam_odom_arm">
    </gazebo>
  <joint name="base_to_cam_odom_arm" type="fixed">
    <parent link="base_link"/>
    <child link="cam_odom_arm"/>
    <axis xyz="0 1 0"/>
    <origin xyz="0.407790953 -0.007436771 -0.302"/>
    <dynamics damping="0.0" friction="0.0"/>
  </joint>
  <!-- cam_odom_base -->
  <link name="cam_odom_base">
    <visual>
      <geometry>
        <box size=".050 .100 .010"/>
      </geometry>
      <origin rpy="0 0 0" xyz="0 0 0"/>
      <material name="grey"/>
    </visual>
    <collision>
      <geometry>
        <box size=".050 .100 .010"/>
      </geometry>
      <origin rpy="0 0 0" xyz="0 0 0"/>
    </collision>
    <inertial>
      <mass value="1"/>
      <inertia ixx="1.0" ixy="0.0" ixz="0.0" iyy="1.0" iyz="0.0" izz="1.0"/>
    </inertial>
  </link>
  <gazebo reference="cam_odom_base">
    </gazebo>
  <joint name="cam_odom_arm_to_cam_odom_base" type="fixed">
    <parent link="cam_odom_arm"/>
    <child link="cam_odom_base"/>
    <axis xyz="0 1 0"/>
    <origin rpy="0 0.3926875 0" xyz="0 0 0.969868718"/>
    <dynamics damping="0.0" friction="0.0"/>
  </joint>
  <!-- cam -->
  <joint name="cam_odom_base_to_camera_link" type="fixed">
    <parent link="cam_odom_base"/>
    <child link="camera_link"/>
    <axis xyz="0 1 0"/>
    <origin xyz="0 0 0.25"/>
  </joint>
  <link name="camera_link">
    <visual>
      <geometry>
        <box size="0.05 0.05 0.05"/>
      </geometry>
      <origin rpy="0 0 0" xyz="0 0 0"/>
      <material name="black"/>
    </visual>
    <collision>
      <geometry>
        <box size="0.05 0.05 0.05"/>
      </geometry>
      <origin rpy="0 0 0" xyz="0 0 0"/>
    </collision>
    <inertial>
      <mass value="1"/>
      <inertia ixx="1.0" ixy="0.0" ixz="0.0" iyy="1.0" iyz="0.0" izz="1.0"/>
    </inertial>
  </link>
  <!-- arm -->
  <link name="front_arm">
    <visual>
      <geometry>
        <box size="0.4098 .054 .049"/>
      </geometry>
      <origin rpy="0 -0.32792332 0" xyz="0.194 0 0.068"/>
      <material name="grey"/>
    </visual>
    <collision>
      <geometry>
        <box size="0.4098 .054 .049"/>
      </geometry>
      <origin rpy="0 -0.32792332 0" xyz="0.194 0 0.068"/>
    </collision>
    <inertial>
      <mass value="10"/>
      <inertia ixx="1.0" ixy="0.0" ixz="0.0" iyy="1.0" iyz="0.0" izz="1.0"/>
    </inertial>
  </link>
  <gazebo reference="front_arm">
    </gazebo>
  <joint name="base_to_front_arm" type="revolute">
    <parent link="base_link"/>
    <child link="front_arm"/>
    <axis xyz="0 1 0"/>
    <origin xyz="0 0 -0.064"/>
    <limit effort="0.5293" lower="-0.2" upper="0.2" velocity="6.159937255"/>
    <dynamics damping="0.0" friction="0.0"/>
  </joint>
  <!-- arm_ext -->
  <link name="front_arm_ext">
    <visual>
      <geometry>
        <box size="0.1149782588 .019 .025"/>
      </geometry>
      <origin rpy="0 -0.69919259 0" xyz="0.0323 0 0.037"/>
      <material name="grey"/>
    </visual>
    <collision>
      <geometry>
        <box size="0.1149782588 .019 .025"/>
      </geometry>
      <origin rpy="0 -0.69919259 0" xyz="0.0323 0 0.037"/>
    </collision>
    <inertial>
      <mass value="1"/>
      <inertia ixx="1.0" ixy="0.0" ixz="0.0" iyy="1.0" iyz="0.0" izz="1.0"/>
    </inertial>
  </link>
  <gazebo reference="front_arm_ext">
    </gazebo>
  <joint name="front_arm_to_front_arm_ext" type="fixed">
    <parent link="front_arm"/>
    <child link="front_arm_ext"/>
    <origin xyz="0.388 0 0.132"/>
  </joint>
  <!-- arm_mobile_ext_1 -->
  <link name="front_arm_mobile_ext_1">
    <visual>
      <geometry>
        <box size="0.1292948568 .019 .025"/>
      </geometry>
      <origin rpy="0 -1.047621071 0" xyz="-0.0323 0 -0.056"/>
      <material name="grey"/>
    </visual>
    <collision>
      <geometry>
        <box size="0.1292948568 .019 .025"/>
      </geometry>
      <origin rpy="0 -1.047621071 0" xyz="-0.0323 0 -0.056"/>
    </collision>
    <inertial>
      <mass value="1"/>
      <inertia ixx="1.0" ixy="0.0" ixz="0.0" iyy="1.0" iyz="0.0" izz="1.0"/>
    </inertial>
  </link>
  <gazebo reference="front_arm_mobile_ext_1">
    </gazebo>
  <joint name="front_arm_ext_to_front_arm_mobile_ext_1" type="fixed">
    <parent link="front_arm_ext"/>
    <child link="front_arm_mobile_ext_1"/>
    <axis xyz="0 1 0"/>
    <origin xyz="0.0646 0 0.074"/>
    <limit effort="0.5293" lower="0.0" upper="-2.8" velocity="6.159937255"/>
    <dynamics damping="0.0" friction="0.0"/>
  </joint>
  <!-- arm_mobile_ext_2 -->
  <link name="front_arm_mobile_ext_2">
    <visual>
      <geometry>
        <box size="0.1294088096 .019 .025"/>
      </geometry>
      <origin rpy="0 -0.737295256 0" xyz="-0.0479 0 -0.0435"/>
      <material name="grey"/>
    </visual>
    <collision>
      <geometry>
        <box size="0.1294088096 .019 .025"/>
      </geometry>
      <origin rpy="0 -0.737295256 0" xyz="-0.0479 0 -0.0435"/>
    </collision>
    <inertial>
      <mass value="1"/>
      <inertia ixx="1.0" ixy="0.0" ixz="0.0" iyy="1.0" iyz="0.0" izz="1.0"/>
    </inertial>
  </link>
  <gazebo reference="front_arm_mobile_ext_2">
    </gazebo>
  <joint name="front_arm_mobile_ext_1_to_front_arm_mobile_ext_2" type="fixed">
    <parent link="front_arm_mobile_ext_1"/>
    <child link="front_arm_mobile_ext_2"/>
    <axis xyz="0 1 0"/>
    <origin xyz="-0.0646 0 -0.112"/>
    <limit effort="0.5293" lower="0.0" upper="-2.8" velocity="6.159937255"/>
    <dynamics damping="0.0" friction="0.0"/>
    <mimic joint="front_arm_ext_to_front_arm_mobile_ext_1" multiplier="-1" offset="0"/>
  </joint>
  <!-- arm_mobile_ext_3 -->
  <link name="front_arm_mobile_ext_3">
    <visual>
      <geometry>
        <box size="0.1444533143 .019 .025"/>
      </geometry>
      <origin rpy="0 -1.045811364 0" xyz="0.0362 0 0.0625"/>
      <material name="grey"/>
    </visual>
    <collision>
      <geometry>
        <box size="0.1444533143 .019 .025"/>
      </geometry>
      <origin rpy="0 -1.045811364 0" xyz="0.0362 0 0.0625"/>
    </collision>
    <inertial>
      <mass value="1"/>
      <inertia ixx="1.0" ixy="0.0" ixz="0.0" iyy="1.0" iyz="0.0" izz="1.0"/>
    </inertial>
  </link>
  <gazebo reference="front_arm_mobile_ext_3">
    </gazebo>
  <joint name="front_arm_mobile_ext_2_to_front_arm_mobile_ext_3" type="fixed">
    <parent link="front_arm_mobile_ext_2"/>
    <child link="front_arm_mobile_ext_3"/>
    <axis xyz="0 1 0"/>
    <origin xyz="-0.0958 0 -0.087"/>
    <limit effort="0.5293" lower="0.0" upper="-2.8" velocity="6.159937255"/>
    <dynamics damping="0.0" friction="0.0"/>
    <mimic joint="front_arm_ext_to_front_arm_mobile_ext_1" multiplier="1" offset="0"/>
  </joint>
  <!-- arm -->
  <link name="rear_arm">
    <visual>
      <geometry>
        <box size="0.4098 .054 .049"/>
      </geometry>
      <origin rpy="0 0.32792332 0" xyz="-0.194 0 0.068"/>
      <material name="grey"/>
    </visual>
    <collision>
      <geometry>
        <box size="0.4098 .054 .049"/>
      </geometry>
      <origin rpy="0 0.32792332 0" xyz="-0.194 0 0.068"/>
    </collision>
    <inertial>
      <mass value="10"/>
      <inertia ixx="1.0" ixy="0.0" ixz="0.0" iyy="1.0" iyz="0.0" izz="1.0"/>
    </inertial>
  </link>
  <gazebo reference="rear_arm">
    </gazebo>
  <joint name="base_to_rear_arm" type="revolute">
    <parent link="base_link"/>
    <child link="rear_arm"/>
    <axis xyz="0 1 0"/>
    <origin xyz="0 0 -0.064"/>
    <limit effort="0.5293" lower="-0.2" upper="0.2" velocity="6.159937255"/>
    <dynamics damping="0.0" friction="0.0"/>
  </joint>
  <!-- arm_ext -->
  <link name="rear_arm_ext">
    <visual>
      <geometry>
        <box size="0.1149782588 .019 .025"/>
      </geometry>
      <origin rpy="0 0.69919259 0" xyz="-0.0323 0 0.037"/>
      <material name="grey"/>
    </visual>
    <collision>
      <geometry>
        <box size="0.1149782588 .019 .025"/>
      </geometry>
      <origin rpy="0 0.69919259 0" xyz="-0.0323 0 0.037"/>
    </collision>
    <inertial>
      <mass value="1"/>
      <inertia ixx="1.0" ixy="0.0" ixz="0.0" iyy="1.0" iyz="0.0" izz="1.0"/>
    </inertial>
  </link>
  <gazebo reference="rear_arm_ext">
    </gazebo>
  <joint name="rear_arm_to_rear_arm_ext" type="fixed">
    <parent link="rear_arm"/>
    <child link="rear_arm_ext"/>
    <origin xyz="-0.388 0 0.132"/>
  </joint>
  <!-- arm_mobile_ext_1 -->
  <link name="rear_arm_mobile_ext_1">
    <visual>
      <geometry>
        <box size="0.1292948568 .019 .025"/>
      </geometry>
      <origin rpy="0 1.047621071 0" xyz="0.0323 0 -0.056"/>
      <material name="grey"/>
    </visual>
    <collision>
      <geometry>
        <box size="0.1292948568 .019 .025"/>
      </geometry>
      <origin rpy="0 1.047621071 0" xyz="0.0323 0 -0.056"/>
    </collision>
    <inertial>
      <mass value="1"/>
      <inertia ixx="1.0" ixy="0.0" ixz="0.0" iyy="1.0" iyz="0.0" izz="1.0"/>
    </inertial>
  </link>
  <gazebo reference="rear_arm_mobile_ext_1">
    </gazebo>
  <joint name="rear_arm_ext_to_rear_arm_mobile_ext_1" type="fixed">
    <parent link="rear_arm_ext"/>
    <child link="rear_arm_mobile_ext_1"/>
    <axis xyz="0 1 0"/>
    <origin xyz="-0.0646 0 0.074"/>
    <limit effort="0.5293" lower="0.0" upper="2.8" velocity="6.159937255"/>
    <dynamics damping="0.0" friction="0.0"/>
  </joint>
  <!-- arm_mobile_ext_2 -->
  <link name="rear_arm_mobile_ext_2">
    <visual>
      <geometry>
        <box size="0.1294088096 .019 .025"/>
      </geometry>
      <origin rpy="0 0.737295256 0" xyz="0.0479 0 -0.0435"/>
      <material name="grey"/>
    </visual>
    <collision>
      <geometry>
        <box size="0.1294088096 .019 .025"/>
      </geometry>
      <origin rpy="0 0.737295256 0" xyz="0.0479 0 -0.0435"/>
    </collision>
    <inertial>
      <mass value="1"/>
      <inertia ixx="1.0" ixy="0.0" ixz="0.0" iyy="1.0" iyz="0.0" izz="1.0"/>
    </inertial>
  </link>
  <gazebo reference="rear_arm_mobile_ext_2">
    </gazebo>
  <joint name="rear_arm_mobile_ext_1_to_rear_arm_mobile_ext_2" type="fixed">
    <parent link="rear_arm_mobile_ext_1"/>
    <child link="rear_arm_mobile_ext_2"/>
    <axis xyz="0 1 0"/>
    <origin xyz="0.0646 0 -0.112"/>
    <limit effort="0.5293" lower="0.0" upper="2.8" velocity="6.159937255"/>
    <dynamics damping="0.0" friction="0.0"/>
    <mimic joint="rear_arm_ext_to_rear_arm_mobile_ext_1" multiplier="-1" offset="0"/>
  </joint>
  <!-- arm_mobile_ext_3 -->
  <link name="rear_arm_mobile_ext_3">
    <visual>
      <geometry>
        <box size="0.1444533143 .019 .025"/>
      </geometry>
      <origin rpy="0 1.045811364 0" xyz="-0.0362 0 0.0625"/>
      <material name="grey"/>
    </visual>
    <collision>
      <geometry>
        <box size="0.1444533143 .019 .025"/>
      </geometry>
      <origin rpy="0 1.045811364 0" xyz="-0.0362 0 0.0625"/>
    </collision>
    <inertial>
      <mass value="1"/>
      <inertia ixx="1.0" ixy="0.0" ixz="0.0" iyy="1.0" iyz="0.0" izz="1.0"/>
    </inertial>
  </link>
  <gazebo reference="rear_arm_mobile_ext_3">
    </gazebo>
  <joint name="rear_arm_mobile_ext_2_to_rear_arm_mobile_ext_3" type="fixed">
    <parent link="rear_arm_mobile_ext_2"/>
    <child link="rear_arm_mobile_ext_3"/>
    <axis xyz="0 1 0"/>
    <origin xyz="0.0958 0 -0.087"/>
    <limit effort="0.5293" lower="0.0" upper="2.8" velocity="6.159937255"/>
    <dynamics damping="0.0" friction="0.0"/>
    <mimic joint="rear_arm_ext_to_rear_arm_mobile_ext_1" multiplier="1" offset="0"/>
  </joint>
  <!-- triangle_base -->
  <link name="front_triangle_base">
    <visual>
      <geometry>
        <box size="0.080 .010 .010"/>
      </geometry>
      <origin rpy="0 0 1.57075" xyz="0 0 0"/>
      <material name="grey"/>
    </visual>
    <collision>
      <geometry>
        <box size="0.080 .010 .010"/>
      </geometry>
      <origin rpy="0 0 1.57075" xyz="0 0 0"/>
    </collision>
    <inertial>
      <mass value="1"/>
      <inertia ixx="1.0" ixy="0.0" ixz="0.0" iyy="1.0" iyz="0.0" izz="1.0"/>
    </inertial>
  </link>
  <gazebo reference="front_triangle_base">
    </gazebo>
  <joint name="front_arm_mobile_ext_2_to_front_triangle_base" type="fixed">
    <parent link="front_arm_mobile_ext_2"/>
    <child link="front_triangle_base"/>
    <origin rpy="0 0 0" xyz="0.05 0 0.0646474284"/>
    <dynamics damping="0.0" friction="0.0"/>
  </joint>
  <!-- left_triangle_side -->
  <link name="front_left_triangle_side">
    <visual>
      <geometry>
        <box size="0.166865215 .010 .010"/>
      </geometry>
      <origin rpy="0 0 0.242071695" xyz="0.081 -0.02 0"/>
      <material name="grey"/>
    </visual>
    <collision>
      <geometry>
        <box size="0.166865215 .010 .010"/>
      </geometry>
      <origin rpy="0 0 0.242071695" xyz="0.081 -0.02 0"/>
    </collision>
    <inertial>
      <mass value="1"/>
      <inertia ixx="1.0" ixy="0.0" ixz="0.0" iyy="1.0" iyz="0.0" izz="1.0"/>
    </inertial>
  </link>
  <gazebo reference="front_left_triangle_side">
    </gazebo>
  <joint name="front_triangle_base_to_front_left_triangle_side" type="fixed">
    <parent link="front_triangle_base"/>
    <child link="front_left_triangle_side"/>
    <origin rpy="0 1.57075 0" xyz="0 0 0"/>
    <dynamics damping="0.0" friction="0.0"/>
  </joint>
  <!-- right_triangle_side -->
  <link name="front_right_triangle_side">
    <visual>
      <geometry>
        <box size="0.166865215 .010 .010"/>
      </geometry>
      <origin rpy="0 0 -0.242071695" xyz="0.081 0.02 0"/>
      <material name="grey"/>
    </visual>
    <collision>
      <geometry>
        <box size="0.166865215 .010 .010"/>
      </geometry>
      <origin rpy="0 0 -0.242071695" xyz="0.081 0.02 0"/>
    </collision>
    <inertial>
      <mass value="1"/>
      <inertia ixx="1.0" ixy="0.0" ixz="0.0" iyy="1.0" iyz="0.0" izz="1.0"/>
    </inertial>
  </link>
  <gazebo reference="front_right_triangle_side">
    </gazebo>
  <joint name="front_triangle_base_to_front_right_triangle_side" type="fixed">
    <parent link="front_triangle_base"/>
    <child link="front_right_triangle_side"/>
    <origin rpy="0 1.57075 0" xyz="0 0 0"/>
    <dynamics damping="0.0" friction="0.0"/>
  </joint>
  <!-- right_direction_axis -->
  <link name="front_right_direction_axis">
    <visual>
      <geometry>
        <cylinder length="0.399235519" radius="0.005"/>
      </geometry>
      <origin rpy="1.716543599 0 0" xyz="0 -0.1975 -0.029"/>
      <material name="grey"/>
    </visual>
    <collision>
      <geometry>
        <cylinder length="0.399235519" radius="0.005"/>
      </geometry>
      <origin rpy="1.716543599 0 0" xyz="0 -0.1975 -0.029"/>
    </collision>
    <inertial>
      <mass value="1"/>
      <inertia ixx="1.0" ixy="0.0" ixz="0.0" iyy="1.0" iyz="0.0" izz="1.0"/>
    </inertial>
  </link>
  <gazebo reference="front_right_direction_axis">
    </gazebo>
  <joint name="front_triangle_base_to_front_right_direction_axis" type="revolute">
    <parent link="front_triangle_base"/>
    <child link="front_right_direction_axis"/>
    <axis xyz="1 0 0"/>
    <origin rpy="0 0 0" xyz="0 0 -0.162"/>
    <limit effort="0.5293" lower="-0.5" upper="0.5" velocity="6.159937255"/>
    <dynamics damping="0.0" friction="0.0"/>
    <!-- <mimic joint="${prefix}_triangle_base_to_${prefix}_right_balance_support" multiplier="1" offset="0" /> -->
  </joint>
  <!-- left_direction_axis -->
  <link name="front_left_direction_axis">
    <visual>
      <geometry>
        <cylinder length="0.399235519" radius="0.005"/>
      </geometry>
      <origin rpy="1.424956401 0 0" xyz="0 0.1975 -0.029"/>
      <material name="grey"/>
    </visual>
    <collision>
      <geometry>
        <cylinder length="0.399235519" radius="0.005"/>
      </geometry>
      <origin rpy="1.424956401 0 0" xyz="0 0.1975 -0.029"/>
    </collision>
    <inertial>
      <mass value="1"/>
      <inertia ixx="1.0" ixy="0.0" ixz="0.0" iyy="1.0" iyz="0.0" izz="1.0"/>
    </inertial>
  </link>
  <gazebo reference="front_left_direction_axis">
    </gazebo>
  <joint name="front_right_direction_axis_to_front_left_direction_axis" type="fixed">
    <parent link="front_right_direction_axis"/>
    <child link="front_left_direction_axis"/>
    <axis xyz="1 0 0"/>
    <origin rpy="0 0 0" xyz="0 0 0"/>
    <limit effort="0.5293" lower="-1.5" upper="1.5" velocity="6.159937255"/>
    <dynamics damping="0.0" friction="0.0"/>
    <!-- <mimic joint="${prefix}_triangle_base_to_${prefix}_right_balance_support" multiplier="1" offset="0" /> -->
  </joint>
  <!-- right_steering_support -->
  <link name="front_right_steering_support">
    <visual>
      <geometry>
        <cylinder length="0.138610966" radius="0.005"/>
      </geometry>
      <origin rpy="3.047620612 0 0" xyz="0 0.0065 0.069"/>
      <material name="grey"/>
    </visual>
    <collision>
      <geometry>
        <cylinder length="0.138610966" radius="0.005"/>
      </geometry>
      <origin rpy="3.047620612 0 0" xyz="0 0.0065 0.069"/>
    </collision>
    <inertial>
      <mass value="1"/>
      <inertia ixx="1.0" ixy="0.0" ixz="0.0" iyy="1.0" iyz="0.0" izz="1.0"/>
    </inertial>
  </link>
  <gazebo reference="front_right_steering_support">
    </gazebo>
  <joint name="front_right_direction_axis_to_front_right_steering_support" type="revolute">
    <parent link="front_right_direction_axis"/>
    <child link="front_right_steering_support"/>
    <axis xyz="1 0 0"/>
    <origin rpy="0 0 0" xyz="0 -0.395 -0.058"/>
    <limit effort="0.5293" lower="-1.5" upper="1.5" velocity="6.159937255"/>
    <dynamics damping="0.0" friction="0.0"/>
    <!--  <mimic joint="${prefix}_triangle_base_to_${prefix}_right_balance_support" multiplier="-1" offset="0" /> -->
  </joint>
  <!-- left_steering_support -->
  <link name="front_left_steering_support">
    <visual>
      <geometry>
        <cylinder length="0.138610966" radius="0.005"/>
      </geometry>
      <origin rpy="0.093879388 0 0" xyz="0 -0.0065 0.069"/>
      <material name="grey"/>
    </visual>
    <collision>
      <geometry>
        <cylinder length="0.138610966" radius="0.005"/>
      </geometry>
      <origin rpy="0.093879388 0 0" xyz="0 -0.0065 0.069"/>
    </collision>
    <inertial>
      <mass value="1"/>
      <inertia ixx="1.0" ixy="0.0" ixz="0.0" iyy="1.0" iyz="0.0" izz="1.0"/>
    </inertial>
  </link>
  <gazebo reference="front_left_steering_support">
    </gazebo>
  <joint name="front_left_direction_axis_front_left_steering_support" type="revolute">
    <parent link="front_left_direction_axis"/>
    <child link="front_left_steering_support"/>
    <axis xyz="1 0 0"/>
    <origin rpy="0 0 0" xyz="0 0.395 -0.058"/>
    <limit effort="0.5293" lower="-1.5" upper="1.5" velocity="6.159937255"/>
    <dynamics damping="0.0" friction="0.0"/>
    <!-- <mimic joint="${prefix}_triangle_base_to_${prefix}_right_balance_support" multiplier="-1" offset="0" /> -->
  </joint>
  <!-- right_balance_support -->
  <link name="front_right_balance_support">
    <visual>
      <geometry>
        <cylinder length="0.351693048" radius="0.005"/>
      </geometry>
      <origin rpy="1.806073791 0 0" xyz="0 0.171 0.041"/>
      <material name="grey"/>
    </visual>
    <collision>
      <geometry>
        <cylinder length="0.351693048" radius="0.005"/>
      </geometry>
      <origin rpy="1.806073791 0 0" xyz="0 0.171 0.041"/>
    </collision>
    <inertial>
      <mass value="1"/>
      <inertia ixx="1.0" ixy="0.0" ixz="0.0" iyy="1.0" iyz="0.0" izz="1.0"/>
    </inertial>
  </link>
  <gazebo reference="front_right_balance_support">
    </gazebo>
  <joint name="front_right_steering_support_to_front_right_balance_support" type="revolute">
    <parent link="front_right_steering_support"/>
    <child link="front_right_balance_support"/>
    <axis xyz="1 0 0"/>
    <origin rpy="0 0 0" xyz="0 0.013 0.138"/>
    <limit effort="0.5293" lower="-1.5" upper="1.5" velocity="6.159937255"/>
    <dynamics damping="0.0" friction="0.0"/>
  </joint>
  <!-- left_balance_support -->
  <link name="front_left_balance_support">
    <visual>
      <geometry>
        <cylinder length="0.351693048" radius="0.005"/>
      </geometry>
      <origin rpy="1.335426209 0 0" xyz="0 -0.171 0.041"/>
      <material name="grey"/>
    </visual>
    <collision>
      <geometry>
        <cylinder length="0.351693048" radius="0.005"/>
      </geometry>
      <origin rpy="1.335426209 0 0" xyz="0 -0.171 0.041"/>
    </collision>
    <inertial>
      <mass value="1"/>
      <inertia ixx="1.0" ixy="0.0" ixz="0.0" iyy="1.0" iyz="0.0" izz="1.0"/>
    </inertial>
  </link>
  <gazebo reference="front_left_balance_support">
    </gazebo>
  <joint name="front_left_steering_support_to_front_left_balance_support" type="revolute">
    <parent link="front_left_steering_support"/>
    <child link="front_left_balance_support"/>
    <axis xyz="1 0 0"/>
    <origin rpy="0 0 0" xyz="0 -0.013 0.138"/>
    <limit effort="0.5293" lower="-1.5" upper="1.5" velocity="6.159937255"/>
    <dynamics damping="0.0" friction="0.0"/>
    <!-- <mimic joint="${prefix}_triangle_base_to_${prefix}_right_balance_support" multiplier="1" offset="0" /> -->
  </joint>
  <!--<gazebo>
      <joint name="${prefix}_left_balance_to_triangle_loop" type="revolute">
        <parent link="${prefix}_left_triangle_side"/>
        <child link="${prefix}_left_balance_support"/>
        <origin xyz="0 ${-steering_support_proj_y} ${steering_support_proj_z}" rpy="0 0 0"/>
        <limit lower="-1.5" upper="1.5" effort="0.5293" velocity="6.159937255" />
        <dynamics damping="0.0" friction="0.0"/>
        <axis>0 1 0</axis>
      </joint>
    </gazebo>-->
  <gazebo>
    <joint name="front_right_balance_to_triangle_loop" type="revolute">
      <parent>front_right_triangle_side</parent>
      <child>front_right_balance_support</child>
      <pose>0 0 0 0 0 0</pose>
      <axis>
        <xyz>1 0 0</xyz>
      </axis>
    </joint>
  </gazebo>
  <link name="front_left_wheel">
    <visual>
      <origin rpy="1.57075 0 0" xyz="0 0 0"/>
      <geometry>
        <cylinder length="0.146" radius="0.18"/>
      </geometry>
      <material name="black"/>
    </visual>
    <collision>
      <origin rpy="1.57075 0 0" xyz="0 0 0"/>
      <geometry>
        <cylinder length="0.146" radius="0.18"/>
      </geometry>
    </collision>
    <inertial>
      <mass value="5"/>
      <inertia ixx="1.0" ixy="0.0" ixz="0.0" iyy="1.0" iyz="0.0" izz="1.0"/>
    </inertial>
  </link>
  <!-- This block provides the simulator (Gazebo) with information on a few additional
    physical properties. See http://gazebosim.org/tutorials/?tut=ros_urdf for more-->
  <gazebo reference="front_left_wheel">
    <mu1 value="1.0"/>
    <mu2 value="1.0"/>
    <kp value="10000000.0"/>
    <kd value="1.0"/>
    <material>Gazebo/Grey</material>
  </gazebo>
  <joint name="front_left_wheel_joint" type="continuous">
    <parent link="front_left_steering_support"/>
    <child link="front_left_wheel"/>
    <axis xyz="0 1 0"/>
    <origin rpy="0 0 0" xyz="0 0.073 0"/>
    <dynamics damping="0.0" friction="0.0"/>
  </joint>
  <!-- This block connects the wheel joint to an actuator (motor), which informs both
    simulation and visualization of the robot -->
  <transmission name="front_left_wheel_trans">
    <type>transmission_interface/SimpleTransmission</type>
    <joint name="front_left_wheel_joint">
      <hardwareInterface>EffortJointInterface</hardwareInterface>
    </joint>
    <actuator name="front_left_wheel_motor">
      <mechanicalReduction>1</mechanicalReduction>
    </actuator>
  </transmission>
  <!-- This block connects the head_swivel joint to an actuator (motor), which informs both
  simulation and visualization of the robot -->
  <!-- <transmission name="${prefix}_${suffix}_wheel_trans">
    <type>transmission_interface/SimpleTransmission</type>
    <joint name="${prefix}_${suffix}_wheel_joint"/>
    <actuator name="${prefix}_${suffix}_wheel_motor">
      <hardwareInterface>PositionJointInterface</hardwareInterface>
      <mechanicalReduction>1</mechanicalReduction>
    </actuator>
  </transmission>-->
  <link name="front_left_wheel_ext">
    <visual>
      <geometry>
        <cylinder length="0.06" radius="0.03"/>
      </geometry>
      <material name="grey"/>
      <origin rpy="0 0 0" xyz="0 0 0"/>
    </visual>
    <collision>
      <geometry>
        <cylinder length="0.06" radius="0.03"/>
      </geometry>
      <origin rpy="0 0 0" xyz="0 0 0"/>
    </collision>
    <inertial>
      <mass value="0"/>
      <inertia ixx="1.0" ixy="0.0" ixz="0.0" iyy="1.0" iyz="0.0" izz="1.0"/>
    </inertial>
  </link>
  <gazebo reference="front_left_wheel_ext">
    </gazebo>
  <joint name="front_left_wheel_to_front_left_wheel_ext" type="fixed">
    <parent link="front_left_wheel"/>
    <child link="front_left_wheel_ext"/>
    <axis xyz="0 1 0"/>
    <origin rpy="1.57075 0 0" xyz="0 0.103 0"/>
    <dynamics damping="0.0" friction="0.0"/>
  </joint>
  <link name="front_right_wheel">
    <visual>
      <origin rpy="1.57075 0 0" xyz="0 0 0"/>
      <geometry>
        <cylinder length="0.146" radius="0.18"/>
      </geometry>
      <material name="black"/>
    </visual>
    <collision>
      <origin rpy="1.57075 0 0" xyz="0 0 0"/>
      <geometry>
        <cylinder length="0.146" radius="0.18"/>
      </geometry>
    </collision>
    <inertial>
      <mass value="5"/>
      <inertia ixx="1.0" ixy="0.0" ixz="0.0" iyy="1.0" iyz="0.0" izz="1.0"/>
    </inertial>
  </link>
  <!-- This block provides the simulator (Gazebo) with information on a few additional
    physical properties. See http://gazebosim.org/tutorials/?tut=ros_urdf for more-->
  <gazebo reference="front_right_wheel">
    <mu1 value="1.0"/>
    <mu2 value="1.0"/>
    <kp value="10000000.0"/>
    <kd value="1.0"/>
    <material>Gazebo/Grey</material>
  </gazebo>
  <joint name="front_right_wheel_joint" type="continuous">
    <parent link="front_right_steering_support"/>
    <child link="front_right_wheel"/>
    <axis xyz="0 1 0"/>
    <origin rpy="0 0 0" xyz="0 -0.073 0"/>
    <dynamics damping="0.0" friction="0.0"/>
  </joint>
  <!-- This block connects the wheel joint to an actuator (motor), which informs both
    simulation and visualization of the robot -->
  <transmission name="front_right_wheel_trans">
    <type>transmission_interface/SimpleTransmission</type>
    <joint name="front_right_wheel_joint">
      <hardwareInterface>EffortJointInterface</hardwareInterface>
    </joint>
    <actuator name="front_right_wheel_motor">
      <mechanicalReduction>1</mechanicalReduction>
    </actuator>
  </transmission>
  <!-- This block connects the head_swivel joint to an actuator (motor), which informs both
  simulation and visualization of the robot -->
  <!-- <transmission name="${prefix}_${suffix}_wheel_trans">
    <type>transmission_interface/SimpleTransmission</type>
    <joint name="${prefix}_${suffix}_wheel_joint"/>
    <actuator name="${prefix}_${suffix}_wheel_motor">
      <hardwareInterface>PositionJointInterface</hardwareInterface>
      <mechanicalReduction>1</mechanicalReduction>
    </actuator>
  </transmission>-->
  <link name="front_right_wheel_ext">
    <visual>
      <geometry>
        <cylinder length="0.06" radius="0.03"/>
      </geometry>
      <material name="grey"/>
      <origin rpy="0 0 0" xyz="0 0 0"/>
    </visual>
    <collision>
      <geometry>
        <cylinder length="0.06" radius="0.03"/>
      </geometry>
      <origin rpy="0 0 0" xyz="0 0 0"/>
    </collision>
    <inertial>
      <mass value="0"/>
      <inertia ixx="1.0" ixy="0.0" ixz="0.0" iyy="1.0" iyz="0.0" izz="1.0"/>
    </inertial>
  </link>
  <gazebo reference="front_right_wheel_ext">
    </gazebo>
  <joint name="front_right_wheel_to_front_right_wheel_ext" type="fixed">
    <parent link="front_right_wheel"/>
    <child link="front_right_wheel_ext"/>
    <axis xyz="0 1 0"/>
    <origin rpy="1.57075 0 0" xyz="0 -0.103 0"/>
    <dynamics damping="0.0" friction="0.0"/>
  </joint>
  <!-- triangle_base -->
  <link name="rear_triangle_base">
    <visual>
      <geometry>
        <box size="0.080 .010 .010"/>
      </geometry>
      <origin rpy="0 0 1.57075" xyz="0 0 0"/>
      <material name="grey"/>
    </visual>
    <collision>
      <geometry>
        <box size="0.080 .010 .010"/>
      </geometry>
      <origin rpy="0 0 1.57075" xyz="0 0 0"/>
    </collision>
    <inertial>
      <mass value="1"/>
      <inertia ixx="1.0" ixy="0.0" ixz="0.0" iyy="1.0" iyz="0.0" izz="1.0"/>
    </inertial>
  </link>
  <gazebo reference="rear_triangle_base">
    </gazebo>
  <joint name="rear_arm_mobile_ext_2_to_rear_triangle_base" type="fixed">
    <parent link="rear_arm_mobile_ext_2"/>
    <child link="rear_triangle_base"/>
    <origin rpy="0 0 0" xyz="-0.05 0 0.0646474284"/>
    <dynamics damping="0.0" friction="0.0"/>
  </joint>
  <!-- left_triangle_side -->
  <link name="rear_left_triangle_side">
    <visual>
      <geometry>
        <box size="0.166865215 .010 .010"/>
      </geometry>
      <origin rpy="0 0 0.242071695" xyz="0.081 -0.02 0"/>
      <material name="grey"/>
    </visual>
    <collision>
      <geometry>
        <box size="0.166865215 .010 .010"/>
      </geometry>
      <origin rpy="0 0 0.242071695" xyz="0.081 -0.02 0"/>
    </collision>
    <inertial>
      <mass value="1"/>
      <inertia ixx="1.0" ixy="0.0" ixz="0.0" iyy="1.0" iyz="0.0" izz="1.0"/>
    </inertial>
  </link>
  <gazebo reference="rear_left_triangle_side">
    </gazebo>
  <joint name="rear_triangle_base_to_rear_left_triangle_side" type="fixed">
    <parent link="rear_triangle_base"/>
    <child link="rear_left_triangle_side"/>
    <origin rpy="0 1.57075 0" xyz="0 0 0"/>
    <dynamics damping="0.0" friction="0.0"/>
  </joint>
  <!-- right_triangle_side -->
  <link name="rear_right_triangle_side">
    <visual>
      <geometry>
        <box size="0.166865215 .010 .010"/>
      </geometry>
      <origin rpy="0 0 -0.242071695" xyz="0.081 0.02 0"/>
      <material name="grey"/>
    </visual>
    <collision>
      <geometry>
        <box size="0.166865215 .010 .010"/>
      </geometry>
      <origin rpy="0 0 -0.242071695" xyz="0.081 0.02 0"/>
    </collision>
    <inertial>
      <mass value="1"/>
      <inertia ixx="1.0" ixy="0.0" ixz="0.0" iyy="1.0" iyz="0.0" izz="1.0"/>
    </inertial>
  </link>
  <gazebo reference="rear_right_triangle_side">
    </gazebo>
  <joint name="rear_triangle_base_to_rear_right_triangle_side" type="fixed">
    <parent link="rear_triangle_base"/>
    <child link="rear_right_triangle_side"/>
    <origin rpy="0 1.57075 0" xyz="0 0 0"/>
    <dynamics damping="0.0" friction="0.0"/>
  </joint>
  <!-- right_direction_axis -->
  <link name="rear_right_direction_axis">
    <visual>
      <geometry>
        <cylinder length="0.399235519" radius="0.005"/>
      </geometry>
      <origin rpy="1.716543599 0 0" xyz="0 -0.1975 -0.029"/>
      <material name="grey"/>
    </visual>
    <collision>
      <geometry>
        <cylinder length="0.399235519" radius="0.005"/>
      </geometry>
      <origin rpy="1.716543599 0 0" xyz="0 -0.1975 -0.029"/>
    </collision>
    <inertial>
      <mass value="1"/>
      <inertia ixx="1.0" ixy="0.0" ixz="0.0" iyy="1.0" iyz="0.0" izz="1.0"/>
    </inertial>
  </link>
  <gazebo reference="rear_right_direction_axis">
    </gazebo>
  <joint name="rear_triangle_base_to_rear_right_direction_axis" type="revolute">
    <parent link="rear_triangle_base"/>
    <child link="rear_right_direction_axis"/>
    <axis xyz="1 0 0"/>
    <origin rpy="0 0 0" xyz="0 0 -0.162"/>
    <limit effort="0.5293" lower="-0.5" upper="0.5" velocity="6.159937255"/>
    <dynamics damping="0.0" friction="0.0"/>
    <!-- <mimic joint="${prefix}_triangle_base_to_${prefix}_right_balance_support" multiplier="1" offset="0" /> -->
  </joint>
  <!-- left_direction_axis -->
  <link name="rear_left_direction_axis">
    <visual>
      <geometry>
        <cylinder length="0.399235519" radius="0.005"/>
      </geometry>
      <origin rpy="1.424956401 0 0" xyz="0 0.1975 -0.029"/>
      <material name="grey"/>
    </visual>
    <collision>
      <geometry>
        <cylinder length="0.399235519" radius="0.005"/>
      </geometry>
      <origin rpy="1.424956401 0 0" xyz="0 0.1975 -0.029"/>
    </collision>
    <inertial>
      <mass value="1"/>
      <inertia ixx="1.0" ixy="0.0" ixz="0.0" iyy="1.0" iyz="0.0" izz="1.0"/>
    </inertial>
  </link>
  <gazebo reference="rear_left_direction_axis">
    </gazebo>
  <joint name="rear_right_direction_axis_to_rear_left_direction_axis" type="fixed">
    <parent link="rear_right_direction_axis"/>
    <child link="rear_left_direction_axis"/>
    <axis xyz="1 0 0"/>
    <origin rpy="0 0 0" xyz="0 0 0"/>
    <limit effort="0.5293" lower="-1.5" upper="1.5" velocity="6.159937255"/>
    <dynamics damping="0.0" friction="0.0"/>
    <!-- <mimic joint="${prefix}_triangle_base_to_${prefix}_right_balance_support" multiplier="1" offset="0" /> -->
  </joint>
  <!-- right_steering_support -->
  <link name="rear_right_steering_support">
    <visual>
      <geometry>
        <cylinder length="0.138610966" radius="0.005"/>
      </geometry>
      <origin rpy="3.047620612 0 0" xyz="0 0.0065 0.069"/>
      <material name="grey"/>
    </visual>
    <collision>
      <geometry>
        <cylinder length="0.138610966" radius="0.005"/>
      </geometry>
      <origin rpy="3.047620612 0 0" xyz="0 0.0065 0.069"/>
    </collision>
    <inertial>
      <mass value="1"/>
      <inertia ixx="1.0" ixy="0.0" ixz="0.0" iyy="1.0" iyz="0.0" izz="1.0"/>
    </inertial>
  </link>
  <gazebo reference="rear_right_steering_support">
    </gazebo>
  <joint name="rear_right_direction_axis_to_rear_right_steering_support" type="revolute">
    <parent link="rear_right_direction_axis"/>
    <child link="rear_right_steering_support"/>
    <axis xyz="1 0 0"/>
    <origin rpy="0 0 0" xyz="0 -0.395 -0.058"/>
    <limit effort="0.5293" lower="-1.5" upper="1.5" velocity="6.159937255"/>
    <dynamics damping="0.0" friction="0.0"/>
    <!--  <mimic joint="${prefix}_triangle_base_to_${prefix}_right_balance_support" multiplier="-1" offset="0" /> -->
  </joint>
  <!-- left_steering_support -->
  <link name="rear_left_steering_support">
    <visual>
      <geometry>
        <cylinder length="0.138610966" radius="0.005"/>
      </geometry>
      <origin rpy="0.093879388 0 0" xyz="0 -0.0065 0.069"/>
      <material name="grey"/>
    </visual>
    <collision>
      <geometry>
        <cylinder length="0.138610966" radius="0.005"/>
      </geometry>
      <origin rpy="0.093879388 0 0" xyz="0 -0.0065 0.069"/>
    </collision>
    <inertial>
      <mass value="1"/>
      <inertia ixx="1.0" ixy="0.0" ixz="0.0" iyy="1.0" iyz="0.0" izz="1.0"/>
    </inertial>
  </link>
  <gazebo reference="rear_left_steering_support">
    </gazebo>
  <joint name="rear_left_direction_axis_rear_left_steering_support" type="revolute">
    <parent link="rear_left_direction_axis"/>
    <child link="rear_left_steering_support"/>
    <axis xyz="1 0 0"/>
    <origin rpy="0 0 0" xyz="0 0.395 -0.058"/>
    <limit effort="0.5293" lower="-1.5" upper="1.5" velocity="6.159937255"/>
    <dynamics damping="0.0" friction="0.0"/>
    <!-- <mimic joint="${prefix}_triangle_base_to_${prefix}_right_balance_support" multiplier="-1" offset="0" /> -->
  </joint>
  <!-- right_balance_support -->
  <link name="rear_right_balance_support">
    <visual>
      <geometry>
        <cylinder length="0.351693048" radius="0.005"/>
      </geometry>
      <origin rpy="1.806073791 0 0" xyz="0 0.171 0.041"/>
      <material name="grey"/>
    </visual>
    <collision>
      <geometry>
        <cylinder length="0.351693048" radius="0.005"/>
      </geometry>
      <origin rpy="1.806073791 0 0" xyz="0 0.171 0.041"/>
    </collision>
    <inertial>
      <mass value="1"/>
      <inertia ixx="1.0" ixy="0.0" ixz="0.0" iyy="1.0" iyz="0.0" izz="1.0"/>
    </inertial>
  </link>
  <gazebo reference="rear_right_balance_support">
    </gazebo>
  <joint name="rear_right_steering_support_to_rear_right_balance_support" type="revolute">
    <parent link="rear_right_steering_support"/>
    <child link="rear_right_balance_support"/>
    <axis xyz="1 0 0"/>
    <origin rpy="0 0 0" xyz="0 0.013 0.138"/>
    <limit effort="0.5293" lower="-1.5" upper="1.5" velocity="6.159937255"/>
    <dynamics damping="0.0" friction="0.0"/>
  </joint>
  <!-- left_balance_support -->
  <link name="rear_left_balance_support">
    <visual>
      <geometry>
        <cylinder length="0.351693048" radius="0.005"/>
      </geometry>
      <origin rpy="1.335426209 0 0" xyz="0 -0.171 0.041"/>
      <material name="grey"/>
    </visual>
    <collision>
      <geometry>
        <cylinder length="0.351693048" radius="0.005"/>
      </geometry>
      <origin rpy="1.335426209 0 0" xyz="0 -0.171 0.041"/>
    </collision>
    <inertial>
      <mass value="1"/>
      <inertia ixx="1.0" ixy="0.0" ixz="0.0" iyy="1.0" iyz="0.0" izz="1.0"/>
    </inertial>
  </link>
  <gazebo reference="rear_left_balance_support">
    </gazebo>
  <joint name="rear_left_steering_support_to_rear_left_balance_support" type="revolute">
    <parent link="rear_left_steering_support"/>
    <child link="rear_left_balance_support"/>
    <axis xyz="1 0 0"/>
    <origin rpy="0 0 0" xyz="0 -0.013 0.138"/>
    <limit effort="0.5293" lower="-1.5" upper="1.5" velocity="6.159937255"/>
    <dynamics damping="0.0" friction="0.0"/>
    <!-- <mimic joint="${prefix}_triangle_base_to_${prefix}_right_balance_support" multiplier="1" offset="0" /> -->
  </joint>
  <!--<gazebo>
      <joint name="${prefix}_left_balance_to_triangle_loop" type="revolute">
        <parent link="${prefix}_left_triangle_side"/>
        <child link="${prefix}_left_balance_support"/>
        <origin xyz="0 ${-steering_support_proj_y} ${steering_support_proj_z}" rpy="0 0 0"/>
        <limit lower="-1.5" upper="1.5" effort="0.5293" velocity="6.159937255" />
        <dynamics damping="0.0" friction="0.0"/>
        <axis>0 1 0</axis>
      </joint>
    </gazebo>-->
  <gazebo>
    <joint name="rear_right_balance_to_triangle_loop" type="revolute">
      <parent>rear_right_triangle_side</parent>
      <child>rear_right_balance_support</child>
      <pose>0 0 0 0 0 0</pose>
      <axis>
        <xyz>1 0 0</xyz>
      </axis>
    </joint>
  </gazebo>
  <link name="rear_left_wheel">
    <visual>
      <origin rpy="1.57075 0 0" xyz="0 0 0"/>
      <geometry>
        <cylinder length="0.146" radius="0.18"/>
      </geometry>
      <material name="black"/>
    </visual>
    <collision>
      <origin rpy="1.57075 0 0" xyz="0 0 0"/>
      <geometry>
        <cylinder length="0.146" radius="0.18"/>
      </geometry>
    </collision>
    <inertial>
      <mass value="5"/>
      <inertia ixx="1.0" ixy="0.0" ixz="0.0" iyy="1.0" iyz="0.0" izz="1.0"/>
    </inertial>
  </link>
  <!-- This block provides the simulator (Gazebo) with information on a few additional
    physical properties. See http://gazebosim.org/tutorials/?tut=ros_urdf for more-->
  <gazebo reference="rear_left_wheel">
    <mu1 value="1.0"/>
    <mu2 value="1.0"/>
    <kp value="10000000.0"/>
    <kd value="1.0"/>
    <material>Gazebo/Grey</material>
  </gazebo>
  <joint name="rear_left_wheel_joint" type="continuous">
    <parent link="rear_left_steering_support"/>
    <child link="rear_left_wheel"/>
    <axis xyz="0 1 0"/>
    <origin rpy="0 0 0" xyz="0 0.073 0"/>
    <dynamics damping="0.0" friction="0.0"/>
  </joint>
  <!-- This block connects the wheel joint to an actuator (motor), which informs both
    simulation and visualization of the robot -->
  <transmission name="rear_left_wheel_trans">
    <type>transmission_interface/SimpleTransmission</type>
    <joint name="rear_left_wheel_joint">
      <hardwareInterface>EffortJointInterface</hardwareInterface>
    </joint>
    <actuator name="rear_left_wheel_motor">
      <mechanicalReduction>1</mechanicalReduction>
    </actuator>
  </transmission>
  <!-- This block connects the head_swivel joint to an actuator (motor), which informs both
  simulation and visualization of the robot -->
  <!-- <transmission name="${prefix}_${suffix}_wheel_trans">
    <type>transmission_interface/SimpleTransmission</type>
    <joint name="${prefix}_${suffix}_wheel_joint"/>
    <actuator name="${prefix}_${suffix}_wheel_motor">
      <hardwareInterface>PositionJointInterface</hardwareInterface>
      <mechanicalReduction>1</mechanicalReduction>
    </actuator>
  </transmission>-->
  <link name="rear_left_wheel_ext">
    <visual>
      <geometry>
        <cylinder length="0.06" radius="0.03"/>
      </geometry>
      <material name="grey"/>
      <origin rpy="0 0 0" xyz="0 0 0"/>
    </visual>
    <collision>
      <geometry>
        <cylinder length="0.06" radius="0.03"/>
      </geometry>
      <origin rpy="0 0 0" xyz="0 0 0"/>
    </collision>
    <inertial>
      <mass value="0"/>
      <inertia ixx="1.0" ixy="0.0" ixz="0.0" iyy="1.0" iyz="0.0" izz="1.0"/>
    </inertial>
  </link>
  <gazebo reference="rear_left_wheel_ext">
    </gazebo>
  <joint name="rear_left_wheel_to_rear_left_wheel_ext" type="fixed">
    <parent link="rear_left_wheel"/>
    <child link="rear_left_wheel_ext"/>
    <axis xyz="0 1 0"/>
    <origin rpy="1.57075 0 0" xyz="0 0.103 0"/>
    <dynamics damping="0.0" friction="0.0"/>
  </joint>
  <link name="rear_right_wheel">
    <visual>
      <origin rpy="1.57075 0 0" xyz="0 0 0"/>
      <geometry>
        <cylinder length="0.146" radius="0.18"/>
      </geometry>
      <material name="black"/>
    </visual>
    <collision>
      <origin rpy="1.57075 0 0" xyz="0 0 0"/>
      <geometry>
        <cylinder length="0.146" radius="0.18"/>
      </geometry>
    </collision>
    <inertial>
      <mass value="5"/>
      <inertia ixx="1.0" ixy="0.0" ixz="0.0" iyy="1.0" iyz="0.0" izz="1.0"/>
    </inertial>
  </link>
  <!-- This block provides the simulator (Gazebo) with information on a few additional
    physical properties. See http://gazebosim.org/tutorials/?tut=ros_urdf for more-->
  <gazebo reference="rear_right_wheel">
    <mu1 value="1.0"/>
    <mu2 value="1.0"/>
    <kp value="10000000.0"/>
    <kd value="1.0"/>
    <material>Gazebo/Grey</material>
  </gazebo>
  <joint name="rear_right_wheel_joint" type="continuous">
    <parent link="rear_right_steering_support"/>
    <child link="rear_right_wheel"/>
    <axis xyz="0 1 0"/>
    <origin rpy="0 0 0" xyz="0 -0.073 0"/>
    <dynamics damping="0.0" friction="0.0"/>
  </joint>
  <!-- This block connects the wheel joint to an actuator (motor), which informs both
    simulation and visualization of the robot -->
  <transmission name="rear_right_wheel_trans">
    <type>transmission_interface/SimpleTransmission</type>
    <joint name="rear_right_wheel_joint">
      <hardwareInterface>EffortJointInterface</hardwareInterface>
    </joint>
    <actuator name="rear_right_wheel_motor">
      <mechanicalReduction>1</mechanicalReduction>
    </actuator>
  </transmission>
  <!-- This block connects the head_swivel joint to an actuator (motor), which informs both
  simulation and visualization of the robot -->
  <!-- <transmission name="${prefix}_${suffix}_wheel_trans">
    <type>transmission_interface/SimpleTransmission</type>
    <joint name="${prefix}_${suffix}_wheel_joint"/>
    <actuator name="${prefix}_${suffix}_wheel_motor">
      <hardwareInterface>PositionJointInterface</hardwareInterface>
      <mechanicalReduction>1</mechanicalReduction>
    </actuator>
  </transmission>-->
  <link name="rear_right_wheel_ext">
    <visual>
      <geometry>
        <cylinder length="0.06" radius="0.03"/>
      </geometry>
      <material name="grey"/>
      <origin rpy="0 0 0" xyz="0 0 0"/>
    </visual>
    <collision>
      <geometry>
        <cylinder length="0.06" radius="0.03"/>
      </geometry>
      <origin rpy="0 0 0" xyz="0 0 0"/>
    </collision>
    <inertial>
      <mass value="0"/>
      <inertia ixx="1.0" ixy="0.0" ixz="0.0" iyy="1.0" iyz="0.0" izz="1.0"/>
    </inertial>
  </link>
  <gazebo reference="rear_right_wheel_ext">
    </gazebo>
  <joint name="rear_right_wheel_to_rear_right_wheel_ext" type="fixed">
    <parent link="rear_right_wheel"/>
    <child link="rear_right_wheel_ext"/>
    <axis xyz="0 1 0"/>
    <origin rpy="1.57075 0 0" xyz="0 -0.103 0"/>
    <dynamics damping="0.0" friction="0.0"/>
  </joint>
  <!-- Gazebo plugin for ROS Control -->
  <gazebo>
    <plugin filename="libgazebo_ros_control.so" name="gazebo_ros_control">
      <robotNamespace>/iartemis</robotNamespace>
    </plugin>
  </gazebo>
  <!-- Gazebo plugin for Cam -->
  <gazebo reference="camera_link">
    <sensor name="camera1" type="camera">
      <update_rate>30.0</update_rate>
      <camera name="head">
        <horizontal_fov>1.3962634</horizontal_fov>
        <image>
          <width>1280</width>
          <height>1024</height>
          <format>R8G8B8</format>
        </image>
        <clip>
          <near>0.02</near>
          <far>300</far>
        </clip>
        <noise>
          <type>gaussian</type>
          <!-- Noise is sampled independently per pixel on each frame.  
               That pixel's noise value is added to each of its color
               channels, which at that point lie in the range [0,1]. -->
          <mean>0.0</mean>
          <stddev>0.007</stddev>
        </noise>
      </camera>
      <plugin filename="libgazebo_ros_camera.so" name="camera_controller">
        <alwaysOn>true</alwaysOn>
        <updateRate>0.0</updateRate>
        <cameraName>iartemis/camera</cameraName>
        <imageTopicName>image_raw</imageTopicName>
        <cameraInfoTopicName>camera_info</cameraInfoTopicName>
        <frameName>camera_link</frameName>
        <hackBaseline>0.07</hackBaseline>
        <distortionK1>0.0</distortionK1>
        <distortionK2>0.0</distortionK2>
        <distortionK3>0.0</distortionK3>
        <distortionT1>0.0</distortionT1>
        <distortionT2>0.0</distortionT2>
      </plugin>
    </sensor>
  </gazebo>
</robot>
